<?xml version="1.0"?>
<robot xmlns:xacro="http://www.ros.org/wiki/xacro">
<xacro:include filename="intertial_macros.xacro" />

    <material name="white">
        <color rgba="1 1 1 1"/>
    </material> 

    <material name="orange">
        <color rgba="1 0.5 0 1"/>
    </material> 

    <material name="black">
        <color rgba="0 0 0 1"/>
    </material>

    <material name="blue">
        <color rgba="0 0 1 1"/>
    </material> 

<!--    base_link   -->
    <link name="base_link">
    </link>

<!--    chassis_link   -->
    <joint name="chassis_joint" type="fixed">
        <parent link="base_link"/>
        <child link="chassis_link"/>
        <origin xyz="-0.1 0 0"/>
    </joint>

    <link name="chassis_link">
    <visual> 
    <origin xyz="0.15 0 0.075"/>
    
        <geometry>
            <box size="0.3 0.3 0.15"/>
        </geometry>
        <material name="white"/>
    </visual>
    <collision>
       <origin xyz="0.15 0 0.075"/>
    
        <geometry>
            <box size="0.3 0.3 0.15"/>
        </geometry>
    </collision>
    <xacro:inertial_box mass="1.0" x="0.3" y="0.3" z="0.15">
        <origin xyz="0.15 0 0.075"/>
    </xacro:inertial_box>
    
    </link>

    <!-- left_wheel_link   -->
    <joint name="left_wheel_joint" type="continuous">
        <parent link="base_link"/>
        <child link="left_wheel_link"/>
        <origin xyz="0 0.17 0" rpy="-${pi/2} 0 0"/>
        <axis xyz="0 0 1"/>
    </joint>
    <link name="left_wheel_link">
    <visual>
        <geometry>
            <cylinder radius="0.05" length="0.04"/>
        </geometry>
        <material name="blue"/>
    </visual>
    <collision>
        <geometry>
            <cylinder radius="0.05" length="0.04"/>
        </geometry>
       
    </collision>
    <xacro:inertial_cylinder mass="0.1" length="0.04" radius="0.05">
        <origin xyz="0 0 0"/>
    </xacro:inertial_cylinder>  
    </link>

    <!-- right_wheel_link   -->
    <joint name="right_wheel_joint" type="continuous">
        <parent link="base_link"/>
        <child link="right_wheel_link"/>
        <origin xyz="0 -0.17 0" rpy="${pi/2} 0 0"/>
        <axis xyz="0 0 -1"/>
    </joint>
     <link name="right_wheel_link">
    <visual>
        <geometry>
            <cylinder radius="0.05" length="0.04"/>
        </geometry>
        <material name="blue"/>
    </visual>
    <collision>
        <geometry>
            <cylinder radius="0.05" length="0.04"/>
        </geometry>
        <material name="blue"/>
       
    </collision>
    <xacro:inertial_cylinder mass="0.1" length="0.04" radius="0.05">
        <origin xyz="0 0 0"/>
    </xacro:inertial_cylinder>  
    </link>


    <!-- caster_wheel_link   -->
    <joint name="caster_wheel_joint" type="fixed">   <!-- should be on the vorher und weil das Chasis link am Unten liegt wegen dessen Joint  -->
        <parent link="chassis_link"/>
        <child link="caster_wheel_link"/>
        <origin xyz="0.24 0 0"/>
    </joint>
    <link name="caster_wheel_link">
    <visual>
        <geometry>
            <sphere radius="0.05"/>
        </geometry>
        <material name="black"/>
    </visual>
    <collision>
        <geometry>
            <cylinder radius="0.05" length="0.04"/>
        </geometry>
    </collision>
    <xacro:inertial_sphere mass="0.1" radius="0.05">
        <origin xyz="0 0 0"/>
    </xacro:inertial_sphere>            
    </link>




</robot>